2020-07-25 02:49:04,434 ERROR: Exception on /user/john [GET] [in /home/faruk/miniconda3/envs/web_app/lib/python3.8/site-packages/flask/app.py:1891]
Traceback (most recent call last):
  File "/home/faruk/miniconda3/envs/web_app/lib/python3.8/site-packages/flask/app.py", line 2447, in wsgi_app
    response = self.full_dispatch_request()
  File "/home/faruk/miniconda3/envs/web_app/lib/python3.8/site-packages/flask/app.py", line 1952, in full_dispatch_request
    rv = self.handle_user_exception(e)
  File "/home/faruk/miniconda3/envs/web_app/lib/python3.8/site-packages/flask/app.py", line 1821, in handle_user_exception
    reraise(exc_type, exc_value, tb)
  File "/home/faruk/miniconda3/envs/web_app/lib/python3.8/site-packages/flask/_compat.py", line 39, in reraise
    raise value
  File "/home/faruk/miniconda3/envs/web_app/lib/python3.8/site-packages/flask/app.py", line 1950, in full_dispatch_request
    rv = self.dispatch_request()
  File "/home/faruk/miniconda3/envs/web_app/lib/python3.8/site-packages/flask/app.py", line 1936, in dispatch_request
    return self.view_functions[rule.endpoint](**req.view_args)
  File "/home/faruk/miniconda3/envs/web_app/lib/python3.8/site-packages/flask_login/utils.py", line 272, in decorated_view
    return func(*args, **kwargs)
  File "/home/faruk/data/works/web_app/microblog/app/routes.py", line 107, in user
    return render_template('user.html', user=user, posts=posts.items, next_url=next_url, prev_url=prev_url, form=form)
  File "/home/faruk/miniconda3/envs/web_app/lib/python3.8/site-packages/flask/templating.py", line 138, in render_template
    ctx.app.jinja_env.get_or_select_template(template_name_or_list),
  File "/home/faruk/miniconda3/envs/web_app/lib/python3.8/site-packages/jinja2/environment.py", line 930, in get_or_select_template
    return self.get_template(template_name_or_list, parent, globals)
  File "/home/faruk/miniconda3/envs/web_app/lib/python3.8/site-packages/jinja2/environment.py", line 883, in get_template
    return self._load_template(name, self.make_globals(globals))
  File "/home/faruk/miniconda3/envs/web_app/lib/python3.8/site-packages/jinja2/environment.py", line 857, in _load_template
    template = self.loader.load(self, name, globals)
  File "/home/faruk/miniconda3/envs/web_app/lib/python3.8/site-packages/jinja2/loaders.py", line 127, in load
    code = environment.compile(source, name, filename)
  File "/home/faruk/miniconda3/envs/web_app/lib/python3.8/site-packages/jinja2/environment.py", line 638, in compile
    self.handle_exception(source=source_hint)
  File "/home/faruk/miniconda3/envs/web_app/lib/python3.8/site-packages/jinja2/environment.py", line 832, in handle_exception
    reraise(*rewrite_traceback_stack(source=source))
  File "/home/faruk/miniconda3/envs/web_app/lib/python3.8/site-packages/jinja2/_compat.py", line 28, in reraise
    raise value.with_traceback(tb)
  File "/home/faruk/data/works/web_app/microblog/app/templates/user.html", line 23, in template
    {% elif not current_user.is_following(user) %}
jinja2.exceptions.TemplateSyntaxError: Encountered unknown tag 'elif'. Jinja was looking for the following tags: 'endblock'. The innermost block that needs to be closed is 'block'.
2020-07-25 02:50:40,317 INFO: Microblog Startup [in /home/faruk/data/works/web_app/microblog/app/__init__.py:36]
2020-07-25 02:51:28,396 INFO: Microblog Startup [in /home/faruk/data/works/web_app/microblog/app/__init__.py:36]
2020-07-25 03:05:11,306 INFO: Microblog Startup [in /home/faruk/data/works/web_app/microblog/app/__init__.py:39]
